<?xml version="1.0" ?>
<!-- =================================================================================== -->
<!-- |    This document was autogenerated by xacro from robot.xacro                    | -->
<!-- |    EDITING THIS FILE BY HAND IS NOT RECOMMENDED                                 | -->
<!-- =================================================================================== -->
<robot name="elspider_air">
  <!-- root link can not have interia, so add this link and joint -->
  <link name="base">
    <collision>
      <origin rpy="0 0 0" xyz="0 0 0.02"/>
      <geometry>
        <box size="0.76 0.28 0.13"/>
      </geometry>
    </collision>
  </link>
  <joint name="floating_base" type="fixed">
    <origin rpy="0 0 0" xyz="0 0 0"/>
    <parent link="base"/>
    <child link="trunk"/>
  </joint>
  <link name="trunk">
    <inertial>
      <origin rpy="0 0 0" xyz="0.00000732 0.00000000 0.02428745"/>
      <mass value="15.8991"/>
      <inertia ixx="0.0926086" ixy="-1.892e-05" ixz="1.58e-06" iyy="0.47054913" iyz="0.0" izz="0.53896766"/>
    </inertial>
    <visual>
      <origin rpy="0 0 0" xyz="0 0 0"/>
      <geometry>
        <mesh filename="../meshes/BASE.STL"/>
      </geometry>
      <material name="default_material">
        <color rgba="0.4 0.4 0.4 1"/>
      </material>
    </visual>

  </link>


  <link name="RF_HIP">
    <inertial>
      <origin xyz="-0.01146909 -0.12306389 -0.03643601" rpy="0 0 0" />
      <mass value="1.20924153"/>
      <inertia ixx="0.00506259" ixy="-0.00037922" ixz="-0.00012353" iyy="0.00134204" iyz="-0.00101741" izz="0.00448477"/>
    </inertial>
    <visual>
      <origin xyz="0 0 0" rpy="0 0 0" />
      <geometry>
        <mesh filename="../meshes/RF_HIP.STL"/>
      </geometry>
      <material name="default_material">
        <color rgba="0.4 0.4 0.4 1"/>
      </material>
    </visual>
    <collision>
      <origin rpy="0.35 0 0" xyz="0 -0.075 -0.010"/>
      <geometry>
        <box size="0.08 0.20 0.08"/>
      </geometry>
    </collision>
  </link>
  <!-- right mirror == 1, left mirror == -1 -->
  <joint name="RF_HAA" type="revolute">
    <origin rpy="0 -0 0" xyz="0.3 -0.08 0.011"/>
    <parent link="base"/>
    <child link="RF_HIP"/>
    <axis xyz="0 0 1"/>
    <dynamics damping="0" friction="0"/>
    <limit lower="-0.785" upper="0.785" effort="33.5" velocity="21"/>
  </joint>

  <link name="RF_THIGH">
    <inertial>
      <!-- y approximately euqal to 0 -->
      <origin rpy="0 0 0" xyz="0.11424797 -0.00005753  -0.01976803"/>
      <mass value="0.92523512"/>
      <inertia ixx="0.0006569" ixy="1.48e-06" ixz="0.0001226" iyy="0.00209449" iyz="1.58e-06" izz="0.00237655"/>
    </inertial>
    <visual>
      <origin rpy="0 0 0" xyz="0 0 0"/>
      <geometry>
        <mesh filename="../meshes/RF_THIGH.STL"/>
      </geometry>
      <material name="default_material">
        <color rgba="0.4 0.4 0.4 1"/>
      </material>
    </visual>
    <collision>
      <origin rpy="0 0 0" xyz="0.065 0.00 -0.05"/>
      <geometry>
        <box size="0.20 0.08 0.1"/>
      </geometry>
    </collision>
  </link>
  <joint name="RF_HFE" type="revolute">
    <origin xyz="0.0355 -0.14999 -0.045056" rpy="3.1416 -1.5708 0" />
    <parent link="RF_HIP"/>
    <child link="RF_THIGH"/>
    <axis xyz="0 0 1"/>
    <dynamics damping="0" friction="0"/>
    <limit lower="-0.5233" upper="3.14" effort="33.5" velocity="21"/>
  </joint>
  <link name="RF_SHANK">
    <inertial>
      <origin xyz="0.0 -0.07024046 -0.00923673" rpy="0 0 0" />
      <mass value="0.28148664"/>
      <!-- no mirror in ixy, ixz? -->
      <inertia ixx="0.00256638" ixy="0.0" ixz="0.0" iyy="9.216e-05" iyz="-0.00017328" izz="0.00258818"/>
    </inertial>
    <visual>
      <origin rpy="0 0 0" xyz="0 0 0"/>
      <geometry>
        <mesh filename="../meshes/RF_SHANK.STL"/>
      </geometry>
      <material name="default_material">
        <color rgba="0.4 0.4 0.4 1"/>
      </material>
    </visual>
    <collision>
      <origin rpy="0 0 0" xyz="0 -0.116 -0.018"/>
      <geometry>
        <box size="0.04 0.232 0.04"/>
      </geometry>
    </collision>
  </link>

  <joint name="RF_KFE" type="revolute">
    <!--TODO here in r maybe exist problem -->
    <origin xyz="0.13 0 0" rpy="3.1416 0 1.5708" />
    <parent link="RF_THIGH"/>
    <child link="RF_SHANK"/>
    <axis xyz="0 0 1"/>
    <dynamics damping="0" friction="0"/>
    <limit lower="-0.6978" upper="3.925" effort="33.5" velocity="21"/>
  </joint>

  <link name="RF_FOOT">
    <inertial>
      <!-- xyz approximately euqal to 0 -->
      <origin xyz="0.00000000 -0.0070918 0.00000000" rpy="0 0 0" />
      <mass value="0.01901289"/>
      <inertia ixx="3.96e-06" ixy="0.0" ixz="0.0" iyy="5.73e-06" iyz="0.0" izz="3.96e-06"/>
    </inertial>
    <visual>
      <origin rpy="0 0 0" xyz="0 0 0"/>
      <geometry>
        <mesh filename="../meshes/RF_FOOT.STL"/>
      </geometry>
      <material name="default_material">
        <color rgba="0.4 0.4 0.4 1"/>
      </material>
    </visual>
    <collision>
      <!-- avoid multiple points of contact with the ground -->
      <origin xyz="0 0 0" rpy="0 0 0"/>
      <geometry>
        <sphere radius="0.025"/>
      </geometry>
      <!-- <origin xyz="0 0 0" rpy="0 0 0" />
                <geometry>
                    <mesh filename="../meshes/${name}_FOOT.STL" />
                </geometry> -->
    </collision>
  </link>
  <joint name="RF_FIX" type="fixed" dont_collapse="true">
    <origin rpy="0 0 0" xyz="0 -0.232 -0.018"/>
    <parent link="RF_SHANK"/>
    <child link="RF_FOOT"/>
    <axis xyz="0 0 0"/>
  </joint>
  <transmission name="RF_HAA_tran">
    <type>transmission_interface/SimpleTransmission</type>
    <joint name="RF_HAA">
      <hardwareInterface>hardware_interface/EffortJointInterface</hardwareInterface>
    </joint>
    <actuator name="RF_HAA_motor">
      <hardwareInterface>hardware_interface/EffortJointInterface</hardwareInterface>
      <mechanicalReduction>1</mechanicalReduction>
    </actuator>
  </transmission>
  <transmission name="RF_HFE_tran">
    <type>transmission_interface/SimpleTransmission</type>
    <joint name="RF_HFE">
      <hardwareInterface>hardware_interface/EffortJointInterface</hardwareInterface>
    </joint>
    <actuator name="RF_HFE_motor">
      <hardwareInterface>hardware_interface/EffortJointInterface</hardwareInterface>
      <mechanicalReduction>1</mechanicalReduction>
    </actuator>
  </transmission>
  <transmission name="RF_KFE_tran">
    <type>transmission_interface/SimpleTransmission</type>
    <joint name="RF_KFE">
      <hardwareInterface>hardware_interface/EffortJointInterface</hardwareInterface>
    </joint>
    <actuator name="RF_KFE_motor">
      <hardwareInterface>hardware_interface/EffortJointInterface</hardwareInterface>
      <mechanicalReduction>1</mechanicalReduction>
    </actuator>
  </transmission>
  <!-- foot contacts -->
  <gazebo reference="RF_SHANK">
    <sensor name="RF_foot_contact" type="contact">
      <alwaysOn>true</alwaysOn>
      <update_rate>100</update_rate>
      <plugin filename="libunitreeFootContactPlugin.so" name="contactPlugin"/>
      <contact>
        <collision>RF_SHANK_fixed_joint_lump__RF_FOOT_collision_1</collision>
      </contact>
    </sensor>
  </gazebo>
  <!-- visualization of Foot contacts. -->
  <gazebo reference="RF_FOOT">
    <visual>
      <plugin filename="libunitreeDrawForcePlugin.so" name="drawForcePlugin">
        <topicName>RF_foot_contact</topicName>
      </plugin>
    </visual>
  </gazebo>
  <!-- set friction -->
  <gazebo reference="RF_HIP">
    <mu1>0.2</mu1>
    <mu2>0.2</mu2>
    <self_collide>1</self_collide>
  </gazebo>
  <gazebo reference="RF_THIGH">
    <mu1>0.2</mu1>
    <mu2>0.2</mu2>
    <self_collide>1</self_collide>
  </gazebo>
  <gazebo reference="RF_SHANK">
    <mu1>0.2</mu1>
    <mu2>0.2</mu2>
    <self_collide>1</self_collide>
  </gazebo>
  <gazebo reference="RF_FOOT">
    <mu1>0.6</mu1>
    <mu2>0.6</mu2>
    <self_collide>1</self_collide>
    <!-- soft foot -->
    <!-- <kp value="1000000.0"/>
            <kd value="1.0"/> -->
    <kp value="20.0"/>
    <kd value="10.0"/>
  </gazebo>
  <!-- right mirror == 1, left mirror == -1 -->

  <link name="RM_HIP">
    <inertial>
      <origin xyz="-0.01146909 -0.12306389 -0.03643601" rpy="0 0 0" />
      <mass value="1.20924153"/>
      <inertia ixx="0.00506259" ixy="-0.00037922" ixz="-0.00012353" iyy="0.00134204" iyz="-0.00101741" izz="0.00448477"/>
    </inertial>
    <visual>
      <origin rpy="0 0 0" xyz="0 0 0"/>
      <geometry>
        <mesh filename="../meshes/RM_HIP.STL"/>
      </geometry>
      <material name="default_material">
        <color rgba="0.4 0.4 0.4 1"/>
      </material>
    </visual>
    <collision>
      <origin rpy="0.35 0 0" xyz="0 -0.075 -0.010"/>
      <geometry>
        <box size="0.08 0.20 0.08"/>
      </geometry>
    </collision>
  </link>

  <joint name="RM_HAA" type="revolute">
    <origin rpy="0 -0 0" xyz="0 -0.14 0.011"/>
    <parent link="base"/>
    <child link="RM_HIP"/>
    <axis xyz="0 0 1"/>
    <dynamics damping="0" friction="0"/>
    <limit lower="-0.785" upper="0.785" effort="33.5" velocity="21"/>
  </joint>

  <link name="RM_THIGH">
    <inertial>
      <!-- y approximately euqal to 0 -->
      <origin xyz="0.11424797 -0.00005753  -0.01976803" rpy="0 0 0" />
      <mass value="0.92523512"/>
      <inertia ixx="0.0006569" ixy="1.48e-06" ixz="0.0001226" iyy="0.00209449" iyz="1.58e-06" izz="0.00237655"/>
    </inertial>
    <visual>
      <origin rpy="0 0 0" xyz="0 0 0"/>
      <geometry>
        <mesh filename="../meshes/RM_THIGH.STL"/>
      </geometry>
      <material name="default_material">
        <color rgba="0.4 0.4 0.4 1"/>
      </material>
    </visual>
    <collision>
      <origin xyz="0.065 0.00 -0.05" rpy="0 0 0" />
      <geometry>
        <box size="0.20 0.08 0.1"/>
      </geometry>
    </collision>
  </link>
  <joint name="RM_HFE" type="revolute">
    <origin xyz="0.0355 -0.14999 -0.045056" rpy="3.1416 -1.5708 0" />

    <parent link="RM_HIP"/>
    <child link="RM_THIGH"/>
    <axis xyz="0 0 1"/>
    <dynamics damping="0" friction="0"/>
    <limit lower="-0.5233" upper="3.14" effort="33.5" velocity="21"/>
  </joint>

  <link name="RM_SHANK">
    <inertial>
      <origin xyz="0.0 -0.07024046 -0.00923673" rpy="0 0 0" />
      <mass value="0.28148664"/>
      <!-- no mirror in ixy, ixz? -->
      <inertia ixx="0.00256638" ixy="0.0" ixz="0.0" iyy="9.216e-05" iyz="-0.00017328" izz="0.00258818"/>
    </inertial>
    <visual>
      <origin rpy="0 0 0" xyz="0 0 0"/>
      <geometry>
        <mesh filename="../meshes/RM_SHANK.STL"/>
      </geometry>
      <material name="default_material">
        <color rgba="0.4 0.4 0.4 1"/>
      </material>
    </visual>
    <collision>
      <origin xyz="0 -0.116 -0.018" rpy="0 0 0"/>
      <geometry>
        <box size="0.04 0.232 0.04"/>
      </geometry>
    </collision>
  </link>

  <joint name="RM_KFE" type="revolute">
    <!--TODO here in r maybe exist problem -->
    <origin xyz="0.13 0 0" rpy="3.1416 0 1.5708"/>
    <parent link="RM_THIGH"/>
    <child link="RM_SHANK"/>
    <axis xyz="0 0 1"/>
    <dynamics damping="0" friction="0"/>
    <limit lower="-0.6978" upper="3.925" effort="33.5" velocity="21"/>
  </joint>

  <link name="RM_FOOT">
    <inertial>
      <!-- xyz approximately euqal to 0 -->
      <origin xyz="0.00000000 -0.0070918 0.00000000" rpy="0 0 0"/>
      <mass value="0.01901289"/>
      <inertia ixx="3.96e-06" ixy="0.0" ixz="0.0" iyy="5.73e-06" iyz="0.0" izz="3.96e-06"/>
    </inertial>
    <visual>
      <origin xyz="0 0 0" rpy="0 0 0" />
      <geometry>
        <mesh filename="../meshes/RM_FOOT.STL"/>
      </geometry>
      <material name="default_material">
        <color rgba="0.4 0.4 0.4 1"/>
      </material>
    </visual>
    <collision>
      <!-- avoid multiple points of contact with the ground -->
      <origin rpy="0 0 0" xyz="0 0 0"/>
      <geometry>
        <sphere radius="0.025"/>
      </geometry>
      <!-- <origin xyz="0 0 0" rpy="0 0 0" />
                <geometry>
                    <mesh filename="../meshes/${name}_FOOT.STL" />
                </geometry> -->
    </collision>
  </link>

  <joint name="RM_FIX" type="fixed" dont_collapse="true">
    <origin xyz="0 -0.232 -0.018" rpy="0 0 0" />
    <parent link="RM_SHANK"/>
    <child link="RM_FOOT"/>
    <axis xyz="0 0 0"/>
  </joint>
  <transmission name="RM_HAA_tran">
    <type>transmission_interface/SimpleTransmission</type>
    <joint name="RM_HAA">
      <hardwareInterface>hardware_interface/EffortJointInterface</hardwareInterface>
    </joint>
    <actuator name="RM_HAA_motor">
      <hardwareInterface>hardware_interface/EffortJointInterface</hardwareInterface>
      <mechanicalReduction>1</mechanicalReduction>
    </actuator>
  </transmission>
  <transmission name="RM_HFE_tran">
    <type>transmission_interface/SimpleTransmission</type>
    <joint name="RM_HFE">
      <hardwareInterface>hardware_interface/EffortJointInterface</hardwareInterface>
    </joint>
    <actuator name="RM_HFE_motor">
      <hardwareInterface>hardware_interface/EffortJointInterface</hardwareInterface>
      <mechanicalReduction>1</mechanicalReduction>
    </actuator>
  </transmission>
  <transmission name="RM_KFE_tran">
    <type>transmission_interface/SimpleTransmission</type>
    <joint name="RM_KFE">
      <hardwareInterface>hardware_interface/EffortJointInterface</hardwareInterface>
    </joint>
    <actuator name="RM_KFE_motor">
      <hardwareInterface>hardware_interface/EffortJointInterface</hardwareInterface>
      <mechanicalReduction>1</mechanicalReduction>
    </actuator>
  </transmission>
  <!-- foot contacts -->
  <gazebo reference="RM_SHANK">
    <sensor name="RM_foot_contact" type="contact">
      <alwaysOn>true</alwaysOn>
      <update_rate>100</update_rate>
      <plugin filename="libunitreeFootContactPlugin.so" name="contactPlugin"/>
      <contact>
        <collision>RM_SHANK_fixed_joint_lump__RM_FOOT_collision_1</collision>
      </contact>
    </sensor>
  </gazebo>
  <!-- visualization of Foot contacts. -->
  <gazebo reference="RM_FOOT">
    <visual>
      <plugin filename="libunitreeDrawForcePlugin.so" name="drawForcePlugin">
        <topicName>RM_foot_contact</topicName>
      </plugin>
    </visual>
  </gazebo>
  <!-- set friction -->
  <gazebo reference="RM_HIP">
    <mu1>0.2</mu1>
    <mu2>0.2</mu2>
    <self_collide>1</self_collide>
  </gazebo>
  <gazebo reference="RM_THIGH">
    <mu1>0.2</mu1>
    <mu2>0.2</mu2>
    <self_collide>1</self_collide>
  </gazebo>
  <gazebo reference="RM_SHANK">
    <mu1>0.2</mu1>
    <mu2>0.2</mu2>
    <self_collide>1</self_collide>
  </gazebo>
  <gazebo reference="RM_FOOT">
    <mu1>0.6</mu1>
    <mu2>0.6</mu2>
    <self_collide>1</self_collide>
    <!-- soft foot -->
    <!-- <kp value="1000000.0"/>
            <kd value="1.0"/> -->
    <kp value="20.0"/>
    <kd value="10.0"/>
  </gazebo>
  <!-- right mirror == 1, left mirror == -1 -->

  <link name="RB_HIP">
    <inertial>
      <origin xyz="0.01146909 -0.12306389 -0.03643601" rpy="0 0 0" />
      <mass value="1.20924153"/>
      <inertia ixx="0.00506259" ixy="0.00037922" ixz="0.00012353" iyy="0.00134204" iyz="-0.00101741" izz="0.00448477"/>
    </inertial>
    <visual>
      <origin xyz="0 0 0" rpy="0 0 0"/>
      <geometry>
        <mesh filename="../meshes/RB_HIP.STL"/>
      </geometry>
      <material name="default_material">
        <color rgba="0.4 0.4 0.4 1"/>
      </material>
    </visual>
    <collision>
      <origin rpy="0.35 0 0" xyz="0 -0.075 -0.010"/>
      <geometry>
        <box size="0.08 0.20 0.08"/>
      </geometry>
    </collision>
  </link>

  <joint name="RB_HAA" type="revolute">
    <origin xyz="-0.3 -0.08 0.011" rpy="0 -0 0" />
    <parent link="base"/>
    <child link="RB_HIP"/>
    <axis xyz="0 0 1"/>
    <dynamics damping="0" friction="0"/>
    <limit lower="-0.785" upper="0.785" effort="33.5" velocity="21"/>
  </joint>

  <link name="RB_THIGH">
    <inertial>
      <!-- y approximately euqal to 0 -->
      <origin xyz="0.11424797 -0.00005753  0.01976803" rpy="0 0 0" />
      <mass value="0.92523512"/>
      <inertia ixx="0.0006569" ixy="1.48e-06" ixz="-0.0001226" iyy="0.00209449" iyz="-1.58e-06" izz="0.00237655"/>
    </inertial>
    <visual>
      <origin rpy="0 0 0" xyz="0 0 0"/>
      <geometry>
        <mesh filename="../meshes/RB_THIGH.STL"/>
      </geometry>
      <material name="default_material">
        <color rgba="0.4 0.4 0.4 1"/>
      </material>
    </visual>
    <collision>
      <origin rpy="0 0 0" xyz="0.065 0.00 0.05"/>
      <geometry>
        <box size="0.20 0.08 0.1"/>
      </geometry>
    </collision>
  </link>
  <joint name="RB_HFE" type="revolute">
    <origin xyz="-0.0355 -0.14999 -0.045056" rpy="3.1416 -1.5708 0"/>
    <axis xyz="0 0 1"/>
    <parent link="RB_HIP"/>
    <child link="RB_THIGH"/>
    <dynamics damping="0" friction="0"/>
    <limit lower="-0.5233" upper="3.14" effort="33.5" velocity="21"/>
  </joint>

  <link name="RB_SHANK">
    <inertial>
      <origin rpy="0 0 0" xyz="0.0 -0.07024046 0.00923673"/>
      <mass value="0.28148664"/>
      <!-- no mirror in ixy, ixz? -->
      <inertia ixx="0.00256638" ixy="0.0" ixz="0.0" iyy="9.216e-05" iyz="0.00017328" izz="0.00258818"/>
    </inertial>
    <visual>
      <origin rpy="0 0 0" xyz="0 0 0"/>
      <geometry>
        <mesh filename="../meshes/RB_SHANK.STL"/>
      </geometry>
      <material name="default_material">
        <color rgba="0.4 0.4 0.4 1"/>
      </material>
    </visual>
    <collision>
      <origin rpy="0 0 0" xyz="0 -0.116 0.018"/>
      <geometry>
        <box size="0.04 0.232 0.04"/>
      </geometry>
    </collision>
  </link>

  <joint name="RB_KFE" type="revolute">
    <!--TODO here in r maybe exist problem -->
    <origin xyz="0.13 0 0" rpy="3.1416 0 1.5708" />
    <parent link="RB_THIGH"/>
    <child link="RB_SHANK"/>
    <axis xyz="0 0 1"/>
    <dynamics damping="0" friction="0"/>
    <limit lower="-0.6978" upper="3.925" effort="33.5" velocity="21"/>
  </joint>

  <link name="RB_FOOT">
    <inertial>
      <!-- xyz approximately euqal to 0 -->
      <origin xyz="0.00000000 -0.0070918 0.00000000" rpy="0 0 0" />
      <mass value="0.01901289"/>
      <inertia ixx="3.96e-06" ixy="0.0" ixz="0.0" iyy="5.73e-06" iyz="0.0" izz="3.96e-06"/>
    </inertial>
    <visual>
      <origin rpy="0 0 0" xyz="0 0 0"/>
      <geometry>
        <mesh filename="../meshes/RB_FOOT.STL"/>
      </geometry>
      <material name="default_material">
        <color rgba="0.4 0.4 0.4 1"/>
      </material>
    </visual>
    <collision>
      <!-- avoid multiple points of contact with the ground -->
      <origin rpy="0 0 0" xyz="0 0 0"/>
      <geometry>
        <sphere radius="0.025"/>
      </geometry>
      <!-- <origin xyz="0 0 0" rpy="0 0 0" />
                <geometry>
                    <mesh filename="../meshes/${name}_FOOT.STL" />
                </geometry> -->
    </collision>
  </link>

  <joint name="RB_FIX" type="fixed" dont_collapse="true">
    <origin xyz="0 -0.232 0.018" rpy="0 0 0" />
    <parent link="RB_SHANK"/>
    <child link="RB_FOOT"/>
    <axis xyz="0 0 0"/>
  </joint>
  <transmission name="RB_HAA_tran">
    <type>transmission_interface/SimpleTransmission</type>
    <joint name="RB_HAA">
      <hardwareInterface>hardware_interface/EffortJointInterface</hardwareInterface>
    </joint>
    <actuator name="RB_HAA_motor">
      <hardwareInterface>hardware_interface/EffortJointInterface</hardwareInterface>
      <mechanicalReduction>1</mechanicalReduction>
    </actuator>
  </transmission>
  <transmission name="RB_HFE_tran">
    <type>transmission_interface/SimpleTransmission</type>
    <joint name="RB_HFE">
      <hardwareInterface>hardware_interface/EffortJointInterface</hardwareInterface>
    </joint>
    <actuator name="RB_HFE_motor">
      <hardwareInterface>hardware_interface/EffortJointInterface</hardwareInterface>
      <mechanicalReduction>1</mechanicalReduction>
    </actuator>
  </transmission>
  <transmission name="RB_KFE_tran">
    <type>transmission_interface/SimpleTransmission</type>
    <joint name="RB_KFE">
      <hardwareInterface>hardware_interface/EffortJointInterface</hardwareInterface>
    </joint>
    <actuator name="RB_KFE_motor">
      <hardwareInterface>hardware_interface/EffortJointInterface</hardwareInterface>
      <mechanicalReduction>1</mechanicalReduction>
    </actuator>
  </transmission>
  <!-- foot contacts -->
  <gazebo reference="RB_SHANK">
    <sensor name="RB_foot_contact" type="contact">
      <alwaysOn>true</alwaysOn>
      <update_rate>100</update_rate>
      <plugin filename="libunitreeFootContactPlugin.so" name="contactPlugin"/>
      <contact>
        <collision>RB_SHANK_fixed_joint_lump__RB_FOOT_collision_1</collision>
      </contact>
    </sensor>
  </gazebo>
  <!-- visualization of Foot contacts. -->
  <gazebo reference="RB_FOOT">
    <visual>
      <plugin filename="libunitreeDrawForcePlugin.so" name="drawForcePlugin">
        <topicName>RB_foot_contact</topicName>
      </plugin>
    </visual>
  </gazebo>
  <!-- set friction -->
  <gazebo reference="RB_HIP">
    <mu1>0.2</mu1>
    <mu2>0.2</mu2>
    <self_collide>1</self_collide>
  </gazebo>
  <gazebo reference="RB_THIGH">
    <mu1>0.2</mu1>
    <mu2>0.2</mu2>
    <self_collide>1</self_collide>
  </gazebo>
  <gazebo reference="RB_SHANK">
    <mu1>0.2</mu1>
    <mu2>0.2</mu2>
    <self_collide>1</self_collide>
  </gazebo>
  <gazebo reference="RB_FOOT">
    <mu1>0.6</mu1>
    <mu2>0.6</mu2>
    <self_collide>1</self_collide>
    <!-- soft foot -->
    <!-- <kp value="1000000.0"/>
            <kd value="1.0"/> -->
    <kp value="20.0"/>
    <kd value="10.0"/>
  </gazebo>

  <link name="LF_HIP">
    <inertial>
      <origin xyz="-0.01146909 -0.12306389 0.03643601" rpy="0 0 0" />
      <mass value="1.20924153"/>
      <inertia ixx="0.00506259" ixy="-0.00037922" ixz="0.00012353" iyy="0.00134204" iyz="0.00101741" izz="0.00448477"/>
    </inertial>
    <visual>
      <origin rpy="0 0 0" xyz="0 0 0"/>
      <geometry>
        <mesh filename="../meshes/LF_HIP.STL"/>
      </geometry>
      <material name="default_material">
        <color rgba="0.4 0.4 0.4 1"/>
      </material>
    </visual>
    <collision>
      <origin rpy="-0.35 0 0" xyz="0 -0.075 0.010"/>
      <geometry>
        <box size="0.08 0.20 0.08"/>
      </geometry>
    </collision>
  </link>

  <!-- right mirror == 1, left mirror == -1 -->
  <joint name="LF_HAA" type="revolute">
    <origin xyz="0.3 0.08 0.011" rpy="-3.1416 0 0"/>
    <parent link="base"/>
    <child link="LF_HIP"/>
    <axis xyz="0 0 1"/>
    <dynamics damping="0" friction="0"/>
    <limit lower="-0.785" upper="0.785" effort="33.5" velocity="21"/>
  </joint>

  <link name="LF_THIGH">
    <inertial>
      <!-- y approximately euqal to 0 -->
      <origin xyz="0.11424797 -0.00005753  0.01976803" rpy="0 0 0"/>
      <mass value="0.92523512"/>
      <inertia ixx="0.0006569" ixy="1.48e-06" ixz="-0.0001226" iyy="0.00209449" iyz="-1.58e-06" izz="0.00237655"/>
    </inertial>
    <visual>
      <origin rpy="0 0 0" xyz="0 0 0"/>
      <geometry>
        <mesh filename="../meshes/LF_THIGH.STL"/>
      </geometry>
      <material name="default_material">
        <color rgba="0.4 0.4 0.4 1"/>
      </material>
    </visual>
    <collision>
      <origin rpy="0 0 0" xyz="0.065 0.00 0.05"/>
      <geometry>
        <box size="0.20 0.08 0.1"/>
      </geometry>
    </collision>
  </link>

  <joint name="LF_HFE" type="revolute">
    <origin xyz="0.0355 -0.14999 0.045056" rpy="3.1416 1.5708 0" />
    <axis xyz="0 0 1"/>
    <parent link="LF_HIP"/>
    <child link="LF_THIGH"/>
    <dynamics damping="0" friction="0"/>
    <limit lower="-0.5233" upper="3.14" effort="33.5" velocity="21"/>
  </joint>
  <link name="LF_SHANK">
    <inertial>
      <origin xyz="-0.0 -0.07024046 0.00923673" rpy="0 0 0" />
      <mass value="0.28148664"/>
      <!-- no mirror in ixy, ixz? -->
      <inertia ixx="0.00256638" ixy="0.0" ixz="0.0" iyy="9.216e-05" iyz="0.00017328" izz="0.00258818"/>
    </inertial>
    <visual>
      <origin rpy="0 0 0" xyz="0 0 0"/>
      <geometry>
        <mesh filename="../meshes/LF_SHANK.STL"/>
      </geometry>
      <material name="default_material">
        <color rgba="0.4 0.4 0.4 1"/>
      </material>
    </visual>
    <collision>
      <origin rpy="0 0 0" xyz="0 -0.116 0.018"/>
      <geometry>
        <box size="0.04 0.232 0.04"/>
      </geometry>
    </collision>
  </link>

  <joint name="LF_KFE" type="revolute">
    <!--TODO here in r maybe exist problem -->
    <origin xyz="0.13 0 0" rpy="-3.1416 0 1.5708"/>
    <parent link="LF_THIGH"/>
    <child link="LF_SHANK"/>
    <axis xyz="0 0 1"/>
    <dynamics damping="0" friction="0"/>
    <limit effort="33.5" lower="-0.6978" upper="3.925" velocity="21"/>
  </joint>


  <link name="LF_FOOT">
    <inertial>
      <!-- xyz approximately euqal to 0 -->
      <origin rpy="0 0 0" xyz="0.00000000 -0.0070918 0.00000000"/>
      <mass value="0.01901289"/>
      <inertia ixx="3.96e-06" ixy="-0.0" ixz="0.0" iyy="5.73e-06" iyz="-0.0" izz="3.96e-06"/>
    </inertial>
    <visual>
      <origin rpy="0 0 0" xyz="0 0 0"/>
      <geometry>
        <mesh filename="../meshes/LF_FOOT.STL"/>
      </geometry>
      <material name="default_material">
        <color rgba="0.4 0.4 0.4 1"/>
      </material>
    </visual>
    <collision>
      <!-- avoid multiple points of contact with the ground -->
      <origin rpy="0 0 0" xyz="0 0 0"/>
      <geometry>
        <sphere radius="0.025"/>
      </geometry>
      <!-- <origin xyz="0 0 0" rpy="0 0 0" />
                <geometry>
                    <mesh filename="../meshes/${name}_FOOT.STL" />
                </geometry> -->
    </collision>
  </link>

  <joint dont_collapse="true" name="LF_FIX" type="fixed">
    <origin rpy="-3.14159265358979 0 -3.14159265358979" xyz="0 -0.232 0.018"/>
    <parent link="LF_SHANK"/>
    <child link="LF_FOOT"/>
    <axis xyz="0 0 0"/>
  </joint>

  <transmission name="LF_HAA_tran">
    <type>transmission_interface/SimpleTransmission</type>
    <joint name="LF_HAA">
      <hardwareInterface>hardware_interface/EffortJointInterface</hardwareInterface>
    </joint>
    <actuator name="LF_HAA_motor">
      <hardwareInterface>hardware_interface/EffortJointInterface</hardwareInterface>
      <mechanicalReduction>1</mechanicalReduction>
    </actuator>
  </transmission>
  <transmission name="LF_HFE_tran">
    <type>transmission_interface/SimpleTransmission</type>
    <joint name="LF_HFE">
      <hardwareInterface>hardware_interface/EffortJointInterface</hardwareInterface>
    </joint>
    <actuator name="LF_HFE_motor">
      <hardwareInterface>hardware_interface/EffortJointInterface</hardwareInterface>
      <mechanicalReduction>1</mechanicalReduction>
    </actuator>
  </transmission>
  <transmission name="LF_KFE_tran">
    <type>transmission_interface/SimpleTransmission</type>
    <joint name="LF_KFE">
      <hardwareInterface>hardware_interface/EffortJointInterface</hardwareInterface>
    </joint>
    <actuator name="LF_KFE_motor">
      <hardwareInterface>hardware_interface/EffortJointInterface</hardwareInterface>
      <mechanicalReduction>1</mechanicalReduction>
    </actuator>
  </transmission>
  <!-- foot contacts -->
  <gazebo reference="LF_SHANK">
    <sensor name="LF_foot_contact" type="contact">
      <alwaysOn>true</alwaysOn>
      <update_rate>100</update_rate>
      <plugin filename="libunitreeFootContactPlugin.so" name="contactPlugin"/>
      <contact>
        <collision>LF_SHANK_fixed_joint_lump__LF_FOOT_collision_1</collision>
      </contact>
    </sensor>
  </gazebo>
  <!-- visualization of Foot contacts. -->
  <gazebo reference="LF_FOOT">
    <visual>
      <plugin filename="libunitreeDrawForcePlugin.so" name="drawForcePlugin">
        <topicName>LF_foot_contact</topicName>
      </plugin>
    </visual>
  </gazebo>
  <!-- set friction -->
  <gazebo reference="LF_HIP">
    <mu1>0.2</mu1>
    <mu2>0.2</mu2>
    <self_collide>1</self_collide>
  </gazebo>
  <gazebo reference="LF_THIGH">
    <mu1>0.2</mu1>
    <mu2>0.2</mu2>
    <self_collide>1</self_collide>
  </gazebo>
  <gazebo reference="LF_SHANK">
    <mu1>0.2</mu1>
    <mu2>0.2</mu2>
    <self_collide>1</self_collide>
  </gazebo>
  <gazebo reference="LF_FOOT">
    <mu1>0.6</mu1>
    <mu2>0.6</mu2>
    <self_collide>1</self_collide>
    <!-- soft foot -->
    <!-- <kp value="1000000.0"/>
            <kd value="1.0"/> -->
    <kp value="20.0"/>
    <kd value="10.0"/>
  </gazebo>
  <!-- right mirror == 1, left mirror == -1 -->
  <joint name="LM_HAA" type="revolute">
    <origin rpy="-3.1416 0 0" xyz="0 0.14 0.011"/>
    <parent link="base"/>
    <child link="LM_HIP"/>
    <axis xyz="0 0 1"/>
    <dynamics damping="0" friction="0"/>
    <limit effort="33.5" lower="-0.785" upper="0.785" velocity="21"/>
  </joint>
  <link name="LM_HIP">
    <inertial>
      <origin rpy="0 0 0" xyz="-0.01146909 -0.12306389 0.03643601"/>
      <mass value="1.20924153"/>
      <inertia ixx="0.00506259" ixy="-0.00037922" ixz="0.00012353" iyy="0.00134204" iyz="0.00101741" izz="0.00448477"/>
    </inertial>
    <visual>
      <origin rpy="0 0 0" xyz="0 0 0"/>
      <geometry>
        <mesh filename="../meshes/LM_HIP.STL"/>
      </geometry>
      <material name="default_material">
        <color rgba="0.4 0.4 0.4 1"/>
      </material>
    </visual>
    <collision>
      <origin rpy="-0.35 0 0" xyz="0 -0.075 0.010"/>
      <geometry>
        <box size="0.08 0.20 0.08"/>
      </geometry>
    </collision>
  </link>

  <link name="LM_THIGH">
    <inertial>
      <!-- y approximately euqal to 0 -->
      <origin rpy="0 0 0" xyz="0.11424797 -0.00005753  0.01976803"/>
      <mass value="0.92523512"/>
      <inertia ixx="0.0006569" ixy="1.48e-06" ixz="-0.0001226" iyy="0.00209449" iyz="-1.58e-06" izz="0.00237655"/>
    </inertial>
    <visual>
      <origin rpy="0 0 0" xyz="0 0 0"/>
      <geometry>
        <mesh filename="../meshes/LM_THIGH.STL"/>
      </geometry>
      <material name="default_material">
        <color rgba="0.4 0.4 0.4 1"/>
      </material>
    </visual>
    <collision>
      <origin rpy="0 0 0" xyz="0.065 0.00 0.05"/>
      <geometry>
        <box size="0.20 0.08 0.1"/>
      </geometry>
    </collision>
  </link>
  <joint name="LM_HFE" type="revolute">
    <origin xyz="0.0355 -0.14999 0.045056" rpy="3.1416 1.5708 0" />
    <axis xyz="0 0 1"/>
    <parent link="LM_HIP"/>
    <child link="LM_THIGH"/>
    <dynamics damping="0" friction="0"/>
    <limit effort="33.5" lower="-0.5233" upper="3.14" velocity="21"/>
  </joint>

  <link name="LM_SHANK">
    <inertial>
      <origin rpy="0 0 0" xyz="-0.0 -0.07024046 0.00923673"/>
      <mass value="0.28148664"/>
      <!-- no mirror in ixy, ixz? -->
      <inertia ixx="0.00256638" ixy="0.0" ixz="0.0" iyy="9.216e-05" iyz="0.00017328" izz="0.00258818"/>
    </inertial>
    <visual>
      <origin rpy="0 0 0" xyz="0 0 0"/>
      <geometry>
        <mesh filename="../meshes/LM_SHANK.STL"/>
      </geometry>
      <material name="default_material">
        <color rgba="0.4 0.4 0.4 1"/>
      </material>
    </visual>
    <collision>
      <origin rpy="0 0 0" xyz="0 -0.116 0.018"/>
      <geometry>
        <box size="0.04 0.232 0.04"/>
      </geometry>
    </collision>
  </link>

  <joint name="LM_KFE" type="revolute">
    <!--TODO here in r maybe exist problem -->
    <origin xyz="0.13 0 0" rpy="-3.1416 0 1.5708" />
    <parent link="LM_THIGH"/>
    <child link="LM_SHANK"/>
    <axis xyz="0 0 1"/>
    <dynamics damping="0" friction="0"/>
    <limit effort="33.5" lower="-0.6978" upper="3.925" velocity="21"/>
  </joint>

  <link name="LM_FOOT">
    <inertial>
      <!-- xyz approximately euqal to 0 -->
      <origin rpy="0 0 0" xyz="0.00000000 -0.0070918 0.00000000"/>
      <mass value="0.01901289"/>
      <inertia ixx="3.96e-06" ixy="-0.0" ixz="0.0" iyy="5.73e-06" iyz="-0.0" izz="3.96e-06"/>
    </inertial>
    <visual>
      <origin rpy="0 0 0" xyz="0 0 0"/>
      <geometry>
        <mesh filename="../meshes/LM_FOOT.STL"/>
      </geometry>
      <material name="default_material">
        <color rgba="0.4 0.4 0.4 1"/>
      </material>
    </visual>
    <collision>
      <!-- avoid multiple points of contact with the ground -->
      <origin rpy="0 0 0" xyz="0 0 0"/>
      <geometry>
        <sphere radius="0.025"/>
      </geometry>
      <!-- <origin xyz="0 0 0" rpy="0 0 0" />
                <geometry>
                    <mesh filename="../meshes/${name}_FOOT.STL" />
                </geometry> -->
    </collision>
  </link>
  <joint dont_collapse="true" name="LM_FIX" type="fixed">
    <origin rpy="3.14159265358979 0 3.14159265358979" xyz="0 -0.232 0.018"/>
    <parent link="LM_SHANK"/>
    <child link="LM_FOOT"/>
    <axis xyz="0 0 0"/>
  </joint>
  <transmission name="LM_HAA_tran">
    <type>transmission_interface/SimpleTransmission</type>
    <joint name="LM_HAA">
      <hardwareInterface>hardware_interface/EffortJointInterface</hardwareInterface>
    </joint>
    <actuator name="LM_HAA_motor">
      <hardwareInterface>hardware_interface/EffortJointInterface</hardwareInterface>
      <mechanicalReduction>1</mechanicalReduction>
    </actuator>
  </transmission>
  <transmission name="LM_HFE_tran">
    <type>transmission_interface/SimpleTransmission</type>
    <joint name="LM_HFE">
      <hardwareInterface>hardware_interface/EffortJointInterface</hardwareInterface>
    </joint>
    <actuator name="LM_HFE_motor">
      <hardwareInterface>hardware_interface/EffortJointInterface</hardwareInterface>
      <mechanicalReduction>1</mechanicalReduction>
    </actuator>
  </transmission>
  <transmission name="LM_KFE_tran">
    <type>transmission_interface/SimpleTransmission</type>
    <joint name="LM_KFE">
      <hardwareInterface>hardware_interface/EffortJointInterface</hardwareInterface>
    </joint>
    <actuator name="LM_KFE_motor">
      <hardwareInterface>hardware_interface/EffortJointInterface</hardwareInterface>
      <mechanicalReduction>1</mechanicalReduction>
    </actuator>
  </transmission>
  <!-- foot contacts -->
  <gazebo reference="LM_SHANK">
    <sensor name="LM_foot_contact" type="contact">
      <alwaysOn>true</alwaysOn>
      <update_rate>100</update_rate>
      <plugin filename="libunitreeFootContactPlugin.so" name="contactPlugin"/>
      <contact>
        <collision>LM_SHANK_fixed_joint_lump__LM_FOOT_collision_1</collision>
      </contact>
    </sensor>
  </gazebo>
  <!-- visualization of Foot contacts. -->
  <gazebo reference="LM_FOOT">
    <visual>
      <plugin filename="libunitreeDrawForcePlugin.so" name="drawForcePlugin">
        <topicName>LM_foot_contact</topicName>
      </plugin>
    </visual>
  </gazebo>
  <!-- set friction -->
  <gazebo reference="LM_HIP">
    <mu1>0.2</mu1>
    <mu2>0.2</mu2>
    <self_collide>1</self_collide>
  </gazebo>
  <gazebo reference="LM_THIGH">
    <mu1>0.2</mu1>
    <mu2>0.2</mu2>
    <self_collide>1</self_collide>
  </gazebo>
  <gazebo reference="LM_SHANK">
    <mu1>0.2</mu1>
    <mu2>0.2</mu2>
    <self_collide>1</self_collide>
  </gazebo>
  <gazebo reference="LM_FOOT">
    <mu1>0.6</mu1>
    <mu2>0.6</mu2>
    <self_collide>1</self_collide>
    <!-- soft foot -->
    <!-- <kp value="1000000.0"/>
            <kd value="1.0"/> -->
    <kp value="20.0"/>
    <kd value="10.0"/>
  </gazebo>
  <!-- right mirror == 1, left mirror == -1 -->

  <link name="LB_HIP">
    <inertial>
      <origin rpy="0 0 0" xyz="0.01146909 -0.12306389 0.03643601"/>
      <mass value="1.20924153"/>
      <inertia ixx="0.00506259" ixy="0.00037922" ixz="-0.00012353" iyy="0.00134204" iyz="0.00101741" izz="0.00448477"/>
    </inertial>
    <visual>
      <origin rpy="0 0 0" xyz="0 0 0"/>
      <geometry>
        <mesh filename="../meshes/LB_HIP.STL"/>
      </geometry>
      <material name="default_material">
        <color rgba="0.4 0.4 0.4 1"/>
      </material>
    </visual>
    <collision>
      <origin rpy="-0.35 0 0" xyz="0 -0.075 0.010"/>
      <geometry>
        <box size="0.08 0.20 0.08"/>
      </geometry>
    </collision>
  </link>
  <joint name="LB_HAA" type="revolute">
    <origin rpy="-3.1416 0 0" xyz="-0.3 0.08 0.011"/>
    <parent link="base"/>
    <child link="LB_HIP"/>
    <axis xyz="0 0 1"/>
    <dynamics damping="0" friction="0"/>
    <limit lower="-0.785" upper="0.785" effort="33.5" velocity="21"/>
  </joint>

  <link name="LB_THIGH">
    <inertial>
      <!-- y approximately euqal to 0 -->
      <origin rpy="0 0 0" xyz="0.11424797 -0.00005753  -0.01976803"/>
      <mass value="0.92523512"/>
      <inertia ixx="0.0006569" ixy="1.48e-06" ixz="0.0001226" iyy="0.00209449" iyz="1.58e-06" izz="0.00237655"/>
    </inertial>
    <visual>
      <origin rpy="0 0 0" xyz="0 0 0"/>
      <geometry>
        <mesh filename="../meshes/LB_THIGH.STL"/>
      </geometry>
      <material name="default_material">
        <color rgba="0.4 0.4 0.4 1"/>
      </material>
    </visual>
    <collision>
      <origin rpy="0 0 0" xyz="0.065 0.00 -0.05"/>
      <geometry>
        <box size="0.20 0.08 0.1"/>
      </geometry>
    </collision>
  </link>
  <joint name="LB_HFE" type="revolute">
    <origin xyz="-0.0355 -0.14999 0.045056" rpy="3.1416 1.5708 0" />
    <axis xyz="0 0 1"/>
    <parent link="LB_HIP"/>
    <child link="LB_THIGH"/>
    <dynamics damping="0" friction="0"/>
    <limit effort="33.5" lower="-0.5233" upper="3.14" velocity="21"/>
  </joint>

  <link name="LB_SHANK">
    <inertial>
      <origin rpy="0 0 0" xyz="-0.0 -0.07024046 -0.00923673"/>
      <mass value="0.28148664"/>
      <!-- no mirror in ixy, ixz? -->
      <inertia ixx="0.00256638" ixy="0.0" ixz="0.0" iyy="9.216e-05" iyz="-0.00017328" izz="0.00258818"/>
    </inertial>
    <visual>
      <origin rpy="0 0 0" xyz="0 0 0"/>
      <geometry>
        <mesh filename="../meshes/LB_SHANK.STL"/>
      </geometry>
      <material name="default_material">
        <color rgba="0.4 0.4 0.4 1"/>
      </material>
    </visual>
    <collision>
      <origin rpy="0 0 0" xyz="0 -0.116 -0.018"/>
      <geometry>
        <box size="0.04 0.232 0.04"/>
      </geometry>
    </collision>
  </link>

  <joint name="LB_KFE" type="revolute">
    <!--TODO here in r maybe exist problem -->
    <origin xyz="0.13 0 0" rpy="3.1416 0 1.5708"/>
    <parent link="LB_THIGH"/>
    <child link="LB_SHANK"/>
    <axis xyz="0 0 1"/>
    <dynamics damping="0" friction="0"/>
    <limit effort="33.5" lower="-0.6978" upper="3.925" velocity="21"/>
  </joint>

  <link name="LB_FOOT">
    <inertial>
      <!-- xyz approximately euqal to 0 -->
      <origin rpy="0 0 0" xyz="0.00000000 -0.0070918 0.00000000"/>
      <mass value="0.01901289"/>
      <inertia ixx="3.96e-06" ixy="-0.0" ixz="0.0" iyy="5.73e-06" iyz="-0.0" izz="3.96e-06"/>
    </inertial>
    <visual>
      <origin rpy="0 0 0" xyz="0 0 0"/>
      <geometry>
        <mesh filename="../meshes/LB_FOOT.STL"/>
      </geometry>
      <material name="default_material">
        <color rgba="0.4 0.4 0.4 1"/>
      </material>
    </visual>
    <collision>
      <!-- avoid multiple points of contact with the ground -->
      <origin rpy="0 0 0" xyz="0 0 0"/>
      <geometry>
        <sphere radius="0.025"/>
      </geometry>
      <!-- <origin xyz="0 0 0" rpy="0 0 0" />
                <geometry>
                    <mesh filename="../meshes/${name}_FOOT.STL" />
                </geometry> -->
    </collision>
  </link>
  <joint dont_collapse="true" name="LB_FIX" type="fixed">
    <origin rpy="3.14159265358979 0 3.14159265358979" xyz="0 -0.232 -0.018"/>
    <parent link="LB_SHANK"/>
    <child link="LB_FOOT"/>
    <axis xyz="0 0 0"/>
  </joint>
  <transmission name="LB_HAA_tran">
    <type>transmission_interface/SimpleTransmission</type>
    <joint name="LB_HAA">
      <hardwareInterface>hardware_interface/EffortJointInterface</hardwareInterface>
    </joint>
    <actuator name="LB_HAA_motor">
      <hardwareInterface>hardware_interface/EffortJointInterface</hardwareInterface>
      <mechanicalReduction>1</mechanicalReduction>
    </actuator>
  </transmission>
  <transmission name="LB_HFE_tran">
    <type>transmission_interface/SimpleTransmission</type>
    <joint name="LB_HFE">
      <hardwareInterface>hardware_interface/EffortJointInterface</hardwareInterface>
    </joint>
    <actuator name="LB_HFE_motor">
      <hardwareInterface>hardware_interface/EffortJointInterface</hardwareInterface>
      <mechanicalReduction>1</mechanicalReduction>
    </actuator>
  </transmission>
  <transmission name="LB_KFE_tran">
    <type>transmission_interface/SimpleTransmission</type>
    <joint name="LB_KFE">
      <hardwareInterface>hardware_interface/EffortJointInterface</hardwareInterface>
    </joint>
    <actuator name="LB_KFE_motor">
      <hardwareInterface>hardware_interface/EffortJointInterface</hardwareInterface>
      <mechanicalReduction>1</mechanicalReduction>
    </actuator>
  </transmission>
  <!-- foot contacts -->
  <gazebo reference="LB_SHANK">
    <sensor name="LB_foot_contact" type="contact">
      <alwaysOn>true</alwaysOn>
      <update_rate>100</update_rate>
      <plugin filename="libunitreeFootContactPlugin.so" name="contactPlugin"/>
      <contact>
        <collision>LB_SHANK_fixed_joint_lump__LB_FOOT_collision_1</collision>
      </contact>
    </sensor>
  </gazebo>
  <!-- visualization of Foot contacts. -->
  <gazebo reference="LB_FOOT">
    <visual>
      <plugin filename="libunitreeDrawForcePlugin.so" name="drawForcePlugin">
        <topicName>LB_foot_contact</topicName>
      </plugin>
    </visual>
  </gazebo>
  <!-- set friction -->
  <gazebo reference="LB_HIP">
    <mu1>0.2</mu1>
    <mu2>0.2</mu2>
    <self_collide>1</self_collide>
  </gazebo>
  <gazebo reference="LB_THIGH">
    <mu1>0.2</mu1>
    <mu2>0.2</mu2>
    <self_collide>1</self_collide>
  </gazebo>
  <gazebo reference="LB_SHANK">
    <mu1>0.2</mu1>
    <mu2>0.2</mu2>
    <self_collide>1</self_collide>
  </gazebo>
  <gazebo reference="LB_FOOT">
    <mu1>0.6</mu1>
    <mu2>0.6</mu2>
    <self_collide>1</self_collide>
    <!-- soft foot -->
    <!-- <kp value="1000000.0"/>
            <kd value="1.0"/> -->
    <kp value="20.0"/>
    <kd value="10.0"/>
  </gazebo>
</robot>
